[2024-07-07T19:22:00.333+0000] {taskinstance.py:1165} INFO - Dependencies all met for <TaskInstance: filesensor.waiting_file scheduled__2022-09-22T00:00:00+00:00 [queued]>
[2024-07-07T19:22:00.345+0000] {taskinstance.py:1165} INFO - Dependencies all met for <TaskInstance: filesensor.waiting_file scheduled__2022-09-22T00:00:00+00:00 [queued]>
[2024-07-07T19:22:00.347+0000] {taskinstance.py:1362} INFO - 
--------------------------------------------------------------------------------
[2024-07-07T19:22:00.347+0000] {taskinstance.py:1363} INFO - Starting attempt 1 of 1
[2024-07-07T19:22:00.347+0000] {taskinstance.py:1364} INFO - 
--------------------------------------------------------------------------------
[2024-07-07T19:22:00.365+0000] {taskinstance.py:1383} INFO - Executing <Task(FileSensor): waiting_file> on 2022-09-22 00:00:00+00:00
[2024-07-07T19:22:00.372+0000] {standard_task_runner.py:55} INFO - Started process 16640 to run task
[2024-07-07T19:22:00.376+0000] {standard_task_runner.py:82} INFO - Running: ['***', 'tasks', 'run', 'filesensor', 'waiting_file', 'scheduled__2022-09-22T00:00:00+00:00', '--job-id', '118', '--raw', '--subdir', 'DAGS_FOLDER/7.3-FileSensor.py', '--cfg-path', '/tmp/tmpsf6853g4']
[2024-07-07T19:22:00.377+0000] {standard_task_runner.py:83} INFO - Job 118: Subtask waiting_file
[2024-07-07T19:22:00.444+0000] {task_command.py:376} INFO - Running <TaskInstance: filesensor.waiting_file scheduled__2022-09-22T00:00:00+00:00 [running]> on host 76c37bb8730f
[2024-07-07T19:22:00.527+0000] {taskinstance.py:1592} INFO - Exporting the following env vars:
AIRFLOW_CTX_DAG_OWNER=***
AIRFLOW_CTX_DAG_ID=filesensor
AIRFLOW_CTX_TASK_ID=waiting_file
AIRFLOW_CTX_EXECUTION_DATE=2022-09-22T00:00:00+00:00
AIRFLOW_CTX_TRY_NUMBER=1
AIRFLOW_CTX_DAG_RUN_ID=scheduled__2022-09-22T00:00:00+00:00
[2024-07-07T19:22:00.548+0000] {taskinstance.py:1851} ERROR - Task failed with exception
Traceback (most recent call last):
  File "/home/airflow/.local/lib/python3.7/site-packages/airflow/sensors/base.py", line 189, in execute
    poke_return = self.poke(context)
  File "/home/airflow/.local/lib/python3.7/site-packages/airflow/sensors/filesystem.py", line 55, in poke
    hook = FSHook(self.fs_conn_id)
  File "/home/airflow/.local/lib/python3.7/site-packages/airflow/hooks/filesystem.py", line 38, in __init__
    conn = self.get_connection(conn_id)
  File "/home/airflow/.local/lib/python3.7/site-packages/airflow/hooks/base.py", line 70, in get_connection
    conn = Connection.get_connection_from_secrets(conn_id)
  File "/home/airflow/.local/lib/python3.7/site-packages/airflow/models/connection.py", line 432, in get_connection_from_secrets
    raise AirflowNotFoundException(f"The conn_id `{conn_id}` isn't defined")
airflow.exceptions.AirflowNotFoundException: The conn_id `fs_default` isn't defined
[2024-07-07T19:22:00.552+0000] {taskinstance.py:1406} INFO - Marking task as FAILED. dag_id=filesensor, task_id=waiting_file, execution_date=20220922T000000, start_date=20240707T192200, end_date=20240707T192200
[2024-07-07T19:22:00.566+0000] {standard_task_runner.py:105} ERROR - Failed to execute job 118 for task waiting_file (The conn_id `fs_default` isn't defined; 16640)
[2024-07-07T19:22:00.588+0000] {local_task_job.py:164} INFO - Task exited with return code 1
[2024-07-07T19:22:00.627+0000] {local_task_job.py:273} INFO - 0 downstream tasks scheduled from follow-on schedule check
