[2024-07-07T18:06:34.235+0000] {taskinstance.py:1165} INFO - Dependencies all met for <TaskInstance: monitoring2.tarea4 scheduled__2024-01-01T00:00:00+00:00 [queued]>
[2024-07-07T18:06:34.261+0000] {taskinstance.py:1165} INFO - Dependencies all met for <TaskInstance: monitoring2.tarea4 scheduled__2024-01-01T00:00:00+00:00 [queued]>
[2024-07-07T18:06:34.264+0000] {taskinstance.py:1362} INFO - 
--------------------------------------------------------------------------------
[2024-07-07T18:06:34.265+0000] {taskinstance.py:1363} INFO - Starting attempt 1 of 3
[2024-07-07T18:06:34.265+0000] {taskinstance.py:1364} INFO - 
--------------------------------------------------------------------------------
[2024-07-07T18:06:34.313+0000] {taskinstance.py:1383} INFO - Executing <Task(PythonOperator): tarea4> on 2024-01-01 00:00:00+00:00
[2024-07-07T18:06:34.328+0000] {standard_task_runner.py:55} INFO - Started process 13135 to run task
[2024-07-07T18:06:34.335+0000] {standard_task_runner.py:82} INFO - Running: ['***', 'tasks', 'run', 'monitoring2', 'tarea4', 'scheduled__2024-01-01T00:00:00+00:00', '--job-id', '107', '--raw', '--subdir', 'DAGS_FOLDER/6.2-monitoring.py', '--cfg-path', '/tmp/tmpv5swj52e']
[2024-07-07T18:06:34.344+0000] {standard_task_runner.py:83} INFO - Job 107: Subtask tarea4
[2024-07-07T18:06:34.496+0000] {task_command.py:376} INFO - Running <TaskInstance: monitoring2.tarea4 scheduled__2024-01-01T00:00:00+00:00 [running]> on host 76c37bb8730f
[2024-07-07T18:06:34.699+0000] {taskinstance.py:1592} INFO - Exporting the following env vars:
AIRFLOW_CTX_DAG_OWNER=***
AIRFLOW_CTX_DAG_ID=monitoring2
AIRFLOW_CTX_TASK_ID=tarea4
AIRFLOW_CTX_EXECUTION_DATE=2024-01-01T00:00:00+00:00
AIRFLOW_CTX_TRY_NUMBER=1
AIRFLOW_CTX_DAG_RUN_ID=scheduled__2024-01-01T00:00:00+00:00
[2024-07-07T18:06:34.719+0000] {taskinstance.py:1851} ERROR - Task failed with exception
Traceback (most recent call last):
  File "/home/airflow/.local/lib/python3.7/site-packages/airflow/operators/python.py", line 175, in execute
    return_value = self.execute_callable()
  File "/home/airflow/.local/lib/python3.7/site-packages/airflow/operators/python.py", line 193, in execute_callable
    return self.python_callable(*self.op_args, **self.op_kwargs)
  File "/opt/airflow/dags/6.2-monitoring.py", line 8, in myfunction
    raise Exception
Exception
[2024-07-07T18:06:34.776+0000] {taskinstance.py:1406} INFO - Marking task as UP_FOR_RETRY. dag_id=monitoring2, task_id=tarea4, execution_date=20240101T000000, start_date=20240707T180634, end_date=20240707T180634
[2024-07-07T18:06:34.843+0000] {standard_task_runner.py:105} ERROR - Failed to execute job 107 for task tarea4 (; 13135)
[2024-07-07T18:06:34.889+0000] {local_task_job.py:164} INFO - Task exited with return code 1
[2024-07-07T18:06:34.941+0000] {local_task_job.py:273} INFO - 0 downstream tasks scheduled from follow-on schedule check
